Workbook

Sheet Dashboard
A1: GESTORA — CRUSCOTTO DEL PROGETTO
A2: Aggiornato il 02/10/2026 · versione v1.2.0 · BE e FE sono in fogli separati (prefisso BE · e FE ·)
A4: TEST BACKEND | C4: TEST FRONTEND | D4: ENDPOINT API | H4: FIX E BUG APERTI
A5: =SUM('BE · Test'!D5:D1000) -> 292 | C5: =SUM('FE · Test'!C5:C1000) -> 64 | D5: =COUNTA('BE · Controllers'!A5:A1000) -> 54 | H5: =COUNTIF('Fix e Bug'!H5:H1000,"Aperto")+COUNTIF('Fix e Bug'!H5:H1000,"In corso") -> 1
A7: INDICE DEI FOGLI — clicca sul nome per aprirlo | F7: QUANTE RIGHE IN OGNI FOGLIO
A8: Foglio | B8: Lato | C8: Cosa contiene | D8: Righe
A9: BE · Models | B9: Backend | C9: Entità, campi e vincoli del database | D9: =COUNTA('BE · Models'!A5:A1000) -> 44
A10: BE · DTO | B10: Backend | C10: Forme dei dati in entrata e in uscita | D10: =COUNTA('BE · DTO'!A5:A1000) -> 32
A11: BE · Repository | B11: Backend | C11: Metodi che leggono e scrivono nel database | D11: =COUNTA('BE · Repository'!A5:A1000) -> 43
A12: BE · Services | B12: Backend | C12: Servizi e componenti di supporto | D12: =COUNTA('BE · Services'!A5:A1000) -> 16
A13: BE · Controllers | B13: Backend | C13: Endpoint, ruoli e cosa fanno | D13: =COUNTA('BE · Controllers'!A5:A1000) -> 54
A14: BE · Method | B14: Backend | C14: Metodi di servizi e supporto, in poche parole | D14: =COUNTA('BE · Method'!A5:A1000) -> 65
A15: BE · Validators | B15: Backend | C15: Controlli automatici sui dati in arrivo | D15: =COUNTA('BE · Validators'!A5:A1000) -> 9
A16: BE · Infrastruttura | B16: Backend | C16: Configurazione, gestione errori, avvio, deploy | D16: =COUNTA('BE · Infrastruttura'!A5:A1000) -> 30
A17: BE · Test | B17: Backend | C17: Classi di test del backend | D17: =COUNTA('BE · Test'!A5:A1000) -> 22
A18: BE · Auth e Security | B18: Backend | C18: Login, token, ruoli, protezioni | D18: =COUNTA('BE · Auth e Security'!A5:A1000) -> 25
A19: BE · Jobs | B19: Backend | C19: Lavori automatici notturni | D19: =COUNTA('BE · Jobs'!A5:A1000) -> 2
A20: BE · Migration | B20: Backend | C20: Modifiche allo schema del database | D20: =COUNTA('BE · Migration'!A5:A1000) -> 7
A21: FE · Pagine | B21: Frontend | C21: Schermate, indirizzi e permessi | D21: =COUNTA('FE · Pagine'!A5:A1000) -> 12
A22: FE · Componenti | B22: Frontend | C22: Componenti React e dove si usano | D22: =COUNTA('FE · Componenti'!A5:A1000) -> 28
A23: FE · Hook e API | B23: Frontend | C23: Hook React e chiamate all'API | D23: =COUNTA('FE · Hook e API'!A5:A1000) -> 39
A24: FE · Auth | B24: Frontend | C24: Token, guardie delle pagine, sessione | D24: =COUNTA('FE · Auth'!A5:A1000) -> 13
A25: FE · Test | B25: Frontend | C25: File di test del frontend | D25: =COUNTA('FE · Test'!A5:A1000) -> 9
A26: Appunti e Step | B26: Manuale | C26: Diario di lavoro (manuale) | D26: =COUNTA('Appunti e Step'!C5:C1000) -> 4
A27: Fix e Bug | B27: Manuale | C27: Registro dei difetti (manuale) | D27: =COUNTA('Fix e Bug'!E5:E1000) -> 1
A29: AMBIENTI
A30: Ambiente | B30: Dove | C30: Indirizzo
A31: Frontend produzione | B31: Vercel | C31: https://gestora-project-xi.vercel.app
A32: Backend produzione | B32: Azure App Service F1 | C32: gestora-api-….azurewebsites.net/health
A33: Database produzione | B33: Neon (PostgreSQL) | C33: Pannello Neon
A34: Frontend locale | B34: Vite | C34: http://localhost:5173 | F34: FIX E BUG PER STATO
A35: Backend locale | B35: dotnet run | C35: http://localhost:5099 | F35: Stato | G35: Quanti | H35: Gravità | I35: Aperti
A36: Database locale | B36: PostgreSQL sulla macchina | C36: — | F36: Risolto | G36: =COUNTIF('Fix e Bug'!H5:H1000,"Risolto") -> 0 | H36: Alta | I36: =COUNTIFS('Fix e Bug'!F5:F1000,"Alta",'Fix e Bug'!H5:H1000,"<>Risolto",'Fix e Bug'!H5:H1000,"<>Scartato",'Fix e Bug'!E5:E1000,"<>") -> 0
F37: In corso | G37: =COUNTIF('Fix e Bug'!H5:H1000,"In corso") -> 0 | H37: Media | I37: =COUNTIFS('Fix e Bug'!F5:F1000,"Media",'Fix e Bug'!H5:H1000,"<>Risolto",'Fix e Bug'!H5:H1000,"<>Scartato",'Fix e Bug'!E5:E1000,"<>") -> 0
A38: STACK TECNOLOGICO | F38: Aperto | G38: =COUNTIF('Fix e Bug'!H5:H1000,"Aperto") -> 1 | H38: Bassa | I38: =COUNTIFS('Fix e Bug'!F5:F1000,"Bassa",'Fix e Bug'!H5:H1000,"<>Risolto",'Fix e Bug'!H5:H1000,"<>Scartato",'Fix e Bug'!E5:E1000,"<>") -> 1
A39: Tecnologia | B39: Versione | C39: Lato | F39: Scartato | G39: =COUNTIF('Fix e Bug'!H5:H1000,"Scartato") -> 0
A40: ASP.NET Core / .NET | B40: 9 | C40: Backend
A41: Entity Framework Core | B41: 9.0.9 | C41: Backend
A42: PostgreSQL (Npgsql) | B42: 9.0.4 | C42: Backend
A43: Identity + JWT Bearer | B43: 9.0.9 | C43: Backend
...

Sheet BE · Models
A1: BE · MODELLI — LE TABELLE DEL DATABASE
A2: Una riga per campo. Le entità stanno in GestoraWebApi/Models, la configurazione in Context/GestoraContext.cs. | F2: ← Torna alla Dashboard
A4: Entità | B4: Tabella | C4: Campo | D4: Tipo | E4: Obbligatorio | F4: Note
A5: Zona | B5: Zone | C5: Id | D5: long | E5: Sì | F5: Chiave
A6: Zona | B6: Zone | C6: Nome | D6: string | E6: Sì | F6: Nome della zona (es. Sala, Dehors), max 100 caratteri
A7: Zona | B7: Zone | C7: Attiva | D7: bool | E7: Sì | F7: Spenta = non si usa per nuove prenotazioni
A8: Zona | B8: Zone | C8: Postazioni | D8: lista di Postazione | E8: — | F8: I tavoli della zona
A9: Postazione | B9: Postazioni | C9: Id | D9: long | E9: Sì | F9: Chiave
A10: Postazione | B10: Postazioni | C10: Numero | D10: int | E10: Sì | F10: Numero del tavolo
A11: Postazione | B11: Postazioni | C11: CapienzaMassima | D11: int | E11: Sì | F11: Posti a sedere, qualsiasi numero da 1 in su
A12: Postazione | B12: Postazioni | C12: Attiva | D12: bool | E12: Sì | F12: Spento = non viene assegnato
A13: Postazione | B13: Postazioni | C13: ZonaId | D13: long | E13: Sì | F13: Zona del tavolo
A14: Postazione | B14: Postazioni | C14: PrenotazioniPostazioni | D14: lista | E14: — | F14: Le prenotazioni assegnate al tavolo
A15: FasciaOraria | B15: FasceOrarie | C15: Id | D15: long | E15: Sì | F15: Chiave
... A48: StatoPrenotazione (enum) | B48: — | C48: NonPresentata = 4 | D48: valore | E48: — | F48: Il cliente non si è presentato (segnato di notte)

Sheet BE · DTO
A1: BE · DTO — I DATI CHE VIAGGIANO NELLE CHIAMATE
A2: Non sono tabelle: sono le forme dei dati in entrata e in uscita dall'API. Stanno nelle cartelle DTOs dei servizi. | D2: ← Torna alla Dashboard
A4: DTO | B4: Area | C4: Serve a | D4: Campi principali
A5: ZonaDTO | B5: Zone | C5: Creare, modificare e leggere una zona | D5: Id, Nome, Attiva
A6: PostazioneDTO | B6: Tavoli | C6: Creare e leggere un tavolo | D6: Id, Numero, CapienzaMassima, ZonaId, Attiva
A7: PostazioneUpdateDTO | B7: Tavoli | C7: Modificare un tavolo | D7: Id, Numero, CapienzaMassima, ZonaId, Attiva
A8: PostazioniDisponibiliDTO | B8: Tavoli | C8: Tavoli liberi in una data e fascia | D8: Id, Numero, CapienzaMassima, ZonaId, Unita
A9: AssociaPostazioniDTO | B9: Tavoli | C9: Spostare un tavolo in un'altra zona | D9: PostazioneId, ZonaId
A10: RiepilogoSalaDTO | B10: Tavoli | C10: Riepilogo della sala in cima a Postazioni | D10: TavoliAttivi, PostiTotali, Fasce
A11: RiepilogoFasciaDTO | B11: Tavoli | C11: Posti dei tavoli confrontati col tetto della fascia | D11: GiornoSettimana, orari, MaxCoperti, PostiTavoli, TettoCoperto
A12: FasciaOrariaDTO | B12: Fasce orarie | C12: Creare, modificare e leggere una fascia | D12: Id, OrarioInizio, OrarioFine, GiornoSettimana, MaxCoperti, Attiva
A13: DisponibilitaFasciaDTO | B13: Fasce orarie | C13: Posti liberi in una fascia | D13: FasciaId, PostiTotali, PostiOccupati, PostiDisponibili
A14: PrenotazioneCreateDTO | B14: Prenotazioni | C14: Creare o modificare una prenotazione | D14: DataPrenotazione, NumeroCoperti, FasciaOrariaId, ZonaId, Note, NomeCliente
A15: PrenotazioneDTO | B15: Prenotazioni | C15: Prenotazione restituita dall'API | D15: Id, data, coperti, Stato, orari, Postazioni, NumeroTurno
... A36: ErrorDetails / ErrorItem | B36: Comune | C36: Forma unica delle risposte di errore | D36: StatusCode, Message, Errors (Field, Error)

Sheet BE · Repository
A1: BE · REPOSITORY — LETTURA E SCRITTURA NEL DATABASE
A2: Un repository per tabella. Cartella GestoraWebApi/Repositories. | D2: ← Torna alla Dashboard
A4: Repository | B4: Metodo | C4: Cosa fa | D4: Note
A5: IRepository<T> (base) | B5: GetByIdAsync | C5: Legge un elemento per Id
A6: IRepository<T> (base) | B6: AddAsync | C6: Aggiunge e salva
A7: IRepository<T> (base) | B7: UpdateAsync | C7: Aggiorna e salva
A8: IRepository<T> (base) | B8: DeleteAsync | C8: Elimina
A9: ZonaRepository | B9: GetByNameAsync | C9: Cerca una zona per nome | D9: Serve a evitare nomi doppi
A10: ZonaRepository | B10: GetAllZoneAsync | C10: Tutte le zone
A11: ZonaRepository | B11: GetAllZoneAttiveAsync | C11: Solo le zone attive
A12: ZonaRepository | B12: IsZonaUsataAsync | C12: Dice se la zona ha tavoli | D12: Una zona con tavoli non si elimina
A13: ZonaRepository | B13: UpdateStatoZonaAsync | C13: Accende o spegne la zona
A14: ZonaRepository | B14: (4 metodi base) | C14: Da IRepository<T>
A15: PostazioneRepository | B15: GetAllQueryable | C15: Base per le ricerche sui tavoli
A16: PostazioneRepository | B16: GetByIdAsync | C16: Legge un tavolo
A17: PostazioneRepository | B17: GetPostazioniAttiveAsync | C17: Tavoli attivi
A18: PostazioneRepository | B18: GetPostazioniPerZonaAsync | C18: Tavoli di una zona
A19: PostazioneRepository | B19: GetPostazioniDisponibiliAsync | C19: Tavoli liberi in una data e fascia
A20: PostazioneRepository | B20: HasPrenotazioniFutureAsync | C20: Dice se il tavolo ha prenotazioni future
A21: PostazioneRepository | B21: HasPrenotazioniViveAsync | C21: Dice se il tavolo ha prenotazioni non chiuse | D21: Blocca l'eliminazione
A22: PostazioneRepository | B22: AddAsync | C22: Aggiunge un tavolo
A23: PostazioneRepository | B23: UpdateAsync | C23: Aggiorna un tavolo
A24: PostazioneRepository | B24: DeleteAsync | C24: Elimina un tavolo
A25: FasciaOrariaRepository | B25: GetAllQueryable | C25: Base per le ricerche sulle fasce
A26: FasciaOrariaRepository | B26: GetByIdAsync | C26: Legge una fascia
A27: FasciaOrariaRepository | B27: GetByIdConLockAsync | C27: Legge una fascia bloccandola | D27: FOR UPDATE: due prenotazioni insieme non sforano il tetto
A28: FasciaOrariaRepository | B28: GetAllFasceAsync | C28: Tutte le fasce
A29: FasciaOrariaRepository | B29: GetFasceAttiveAsync | C29: Solo le fasce attive
A30: FasciaOrariaRepository | B30: GetFasceByGiornoAsync | C30: Fasce di un giorno della settimana
A31: FasciaOrariaRepository | B31: CountNumeroCopertiFasciaOrariaAsync | C31: Somma i coperti già prenotati in fascia e data | D31: Serve al controllo del tetto
A32: FasciaOrariaRepository | B32: HasPrenotazioniFutureAsync | C32: Dice se la fascia ha prenotazioni future | D32: Se sì, giorno e orari non si cambiano
A33: FasciaOrariaRepository | B33: IsFasciaUsataAsync | C33: Dice se la fascia è mai stata prenotata | D33: Se sì, non si elimina
A34: FasciaOrariaRepository | B34: AddAsync | C34: Aggiunge una fascia
A35: FasciaOrariaRepository | B35: UpdateAsync | C35: Aggiorna una fascia
A36: FasciaOrariaRepository | B36: DeleteAsync | C36: Elimina una fascia
A37: PrenotazioniRepository | B37: GetAllQueryableAsync | C37: Base per elenco e filtri
A38: PrenotazioniRepository | B38: GetAllPrenotazioniAsync | C38: Tutte le prenotazioni
A39: PrenotazioniRepository | B39: GetPrenotazioniByDataAsync | C39: Prenotazioni di una data
A40: PrenotazioniRepository | B40: GetTrackedByIdAsync | C40: Legge una prenotazione per modificarla
A41: PrenotazioniRepository | B41: BloccaPerModificaAsync | C41: Blocca la riga prima di cambiarla | D41: FOR UPDATE (AUD-M4)
...

Sheet BE · Services
A1: BE · SERVICES — LA LOGICA DEL GESTIONALE
A2: Le regole stanno qui, non nei controller. Cartella GestoraWebApi/Services (motori e supporto anche in Common e Infrastructure). | F2: ← Torna alla Dashboard
A4: Servizio | B4: Tipo | C4: Cosa fa | D4: Usa | E4: Cache | F4: Note
A5: ZonaService | B5: Servizio | C5: Crea, modifica, accende/spegne ed elimina le zone | D5: ZonaRepository, LogActivity | E5: zone_all, zone_attive | F5: Non elimina una zona con tavoli
A6: PostazioneService | B6: Servizio | C6: Gestisce i tavoli e il riepilogo della sala | D6: Postazione, Zona e Fascia repository | E6: postazioni_attive | F6: Non elimina un tavolo con prenotazioni aperte
A7: FasciaOrariaService | B7: Servizio | C7: Gestisce le fasce orarie e i loro tetti | D7: FasciaOrariaRepository, LogActivity | E7: fasce_attive, fasce per giorno | F7: Giorno e orari bloccati se ci sono prenotazioni future
A8: PrenotazioniService | B8: Servizio | C8: Crea, modifica e cambia stato alle prenotazioni | D8: Prenotazioni e Fasce repository, Assegnazione, IClock | E8: — | F8: Il servizio più importante: tetto coperti, regole, job
A9: PostazioneAssignmentService | B9: Servizio | C9: Sceglie i tavoli per una prenotazione | D9: PostazioneRepository, AssegnazioneTavoli | E9: —
A10: DisponibilitaService | B10: Servizio | C10: Dice quali fasce hanno posto in una data | D10: Fasce e Prenotazioni repository, AssegnazioneTavoli | E10: — | F10: Usato anche dalla pagina pubblica
A11: DashboardService | B11: Servizio | C11: Calcola i numeri della dashboard | D11: GestoraContext (sola lettura), IClock | E11: —
A12: LogActivityService | B12: Servizio | C12: Scrive e legge il registro delle azioni | D12: LogActivityRepository | E12: —
A13: UserManager (Identity) | B13: Framework | C13: Gestisce utenti, ruoli e password | D13: Usato direttamente dai controller | E13: — | F13: Non c'è un servizio utenti nostro
A14: AssegnazioneTavoli | B14: Motore | C14: Trova i tavoli che sprecano meno posti | D14: — | E14: — | F14: Max 4 tavoli della stessa zona; bonus testate solo per tavoli da 2
A15: JwtTokenGenerator | B15: Supporto | C15: Crea il token dopo il login | D15: JwtSettings | E15: — | F15: Nel token: Id, email, ruoli, security stamp
A16: SystemClock (IClock) | B16: Supporto | C16: Dà data e ora di Roma, uguali ovunque | D16: — | E16: — | F16: Nei test si usa TestClock
A17: EsecutoreTransazione | B17: Supporto | C17: Esegue un'operazione in transazione, riprovando se il database cade | D17: GestoraContext | E17: —
A18: CacheKeys | B18: Supporto | C18: Nomi delle chiavi della cache | D18: — | E18: 30 minuti
A19: IndirizzoClient | B19: Supporto | C19: Trova l'IP vero di chi chiama | D19: — | E19: — | F19: Legge X-Forwarded-For
A20: Profili AutoMapper (4) | B20: Supporto | C20: Copiano i dati da entità a DTO | D20: — | E20: — | F20: Zona, Postazione, FasciaOraria, Prenotazione

Sheet BE · Controllers
A1: BE · CONTROLLERS — GLI ENDPOINT DELL'API
A2: Indirizzo base /api/{controller}. Pubblico = senza login. Cartella GestoraWebApi/Controllers. | G2: ← Torna alla Dashboard
A3: Endpoint: | B3: =COUNTA(A5:A1000) -> 54
A4: Controller | B4: Verbo | C4: Route | D4: Chi può | E4: Metodo | F4: Cosa fa | G4: Limite
A5: AuthenticationUser | B5: POST | C5: /api/AuthenticationUser/register | D5: Pubblico | E5: Register | F5: Registra un nuovo Cliente
A6: AuthenticationUser | B6: POST | C6: /api/AuthenticationUser/login | D6: Pubblico | E6: Login | F6: Login: restituisce il token | G6: 5 al minuto per IP
A7: AuthenticationUser | B7: GET | C7: /api/AuthenticationUser/get-users | D7: Admin | E7: GetUsers | F7: Elenco utenti con ruoli
A8: AuthenticationUser | B8: GET | C8: /api/AuthenticationUser/get-user/{id} | D8: Admin | E8: GetUserById | F8: Legge un utente
A9: AuthenticationUser | B9: PUT | C9: /api/AuthenticationUser/update-user/{id} | D9: Admin | E9: UpdateUser | F9: Modifica nome o email
A10: AuthenticationUser | B10: DELETE | C10: /api/AuthenticationUser/delete-user/{id} | D10: Admin | E10: DeleteUser | F10: Elimina un utente senza prenotazioni
A11: AuthenticationUser | B11: POST | C11: /api/AuthenticationUser/assign-role | D11: Admin | E11: AssignRole | F11: Dà un ruolo
A12: AuthenticationUser | B12: DELETE | C12: /api/AuthenticationUser/remove-role | D12: Admin | E12: RemoveRole | F12: Toglie un ruolo (l'Admin non lo toglie a sé)
A13: AuthenticationUser | B13: POST | C13: /api/AuthenticationUser/reset-password/{id} | D13: Admin | E13: ResetPassword | F13: L'Admin imposta una nuova password
A14: Setup | B14: GET | C14: /api/Setup/stato | D14: Pubblico | E14: Stato | F14: Dice se esiste già un Admin
A15: Setup | B15: POST | C15: /api/Setup/admin | D15: Pubblico | E15: CreaPrimoAdmin | F15: Crea il primo Admin, poi si chiude | G15: 5 al minuto per IP
A16: Zona | B16: GET | C16: /api/Zona/get-all-zone | D16: Admin, Staff | E16: GetAllZoneAsync | F16: Tutte le zone
A17: Zona | B17: GET | C17: /api/Zona/get-zone-attive | D17: Admin, Staff, Cliente | E17: GetAllZoneAttiveAsync | F17: Solo le zone attive
A18: Zona | B18: GET | C18: /api/Zona/get-zona/{id} | D18: Admin, Staff | E18: GetZonaByIdAsync | F18: Legge una zona
A19: Zona | B19: GET | C19: /api/Zona/is-zona-usata | D19: Admin, Staff | E19: VerificaZonaUsataAsync | F19: Dice se la zona ha tavoli
A20: Zona | B20: POST | C20: /api/Zona/crea-zona | D20: Admin | E20: CreateZonaAsync | F20: Crea una zona
A21: Zona | B21: PUT | C21: /api/Zona/update-zona | D21: Admin | E21: UpdateZonaAsync | F21: Modifica una zona
A22: Zona | B22: PATCH | C22: /api/Zona/update-stato/{id} | D22: Admin | E22: UpdateStatoZonaAsync | F22: Accende o spegne una zona
A23: Zona | B23: DELETE | C23: /api/Zona/delete-zona/{id} | D23: Admin | E23: DeleteZonaAsync | F23: Elimina una zona senza tavoli
A24: Postazione | B24: GET | C24: /api/Postazione/get-postazioni-attive | D24: Admin, Staff, Cliente | E24: GetAllPostazioniAttiveAsync | F24: Tavoli attivi
A25: Postazione | B25: GET | C25: /api/Postazione/get-postazioni-per-zona | D25: Admin, Staff, Cliente | E25: GetPostazioniPerZonaAsync | F25: Tavoli di una zona
A26: Postazione | B26: GET | C26: /api/Postazione/get-postazioni-disponibili | D26: Admin, Staff, Cliente | E26: GetPostazioniDisponibiliAsync | F26: Tavoli liberi in data e fascia
A27: Postazione | B27: GET | C27: /api/Postazione/get-postazione-id | D27: Admin, Staff | E27: GetPostazioneByIdAsync | F27: Legge un tavolo
... A58: (Program.cs) | B58: GET | C58: /health | D58: Pubblico | E58: — | F58: Controlla che API e database rispondano

Sheet BE · Method
A1: BE · METODI — COSA FA OGNI METODO
A2: Metodi dei servizi e dei componenti di supporto. Interno = usato solo dentro la sua classe. I metodi dei repository sono nel foglio BE · Repository. | E2: ← Torna alla Dashboard
A4: Classe | B4: Metodo | C4: Visibilità | D4: Cosa fa | E4: Chiamato da
A5: PrenotazioniService | B5: AddAsync | C5: Pubblico | D5: Crea la prenotazione e assegna i tavoli | E5: PrenotazioneController
A6: PrenotazioniService | B6: UpdateAsync | C6: Pubblico | D6: Modifica e riassegna i tavoli | E6: PrenotazioneController
A7: PrenotazioniService | B7: DeleteAsync | C7: Pubblico | D7: Elimina, solo se annullata | E7: PrenotazioneController
A8: PrenotazioniService | B8: GetByIdAsync | C8: Pubblico | D8: Legge una prenotazione (il Cliente solo le sue) | E8: PrenotazioneController
A9: PrenotazioniService | B9: GetAllPrenotazioniAsync | C9: Pubblico | D9: Elenco a pagine con filtri | E9: PrenotazioneController
A10: PrenotazioniService | B10: GetPrenotazioniByDataAsync | C10: Pubblico | D10: Prenotazioni di una data | E10: PrenotazioneController
A11: PrenotazioniService | B11: GetMiePrenotazioniAsync | C11: Pubblico | D11: Prenotazioni del Cliente collegato | E11: PrenotazioneController
A12: PrenotazioniService | B12: ConfermaPrenotazioneAsync | C12: Pubblico | D12: Segna l'arrivo del cliente, solo nel giorno | E12: PrenotazioneController
A13: PrenotazioniService | B13: CompletePrenotazioneAsync | C13: Pubblico | D13: Chiude una prenotazione in corso | E13: PrenotazioneController
A14: PrenotazioniService | B14: AnnullaPrenotazioneAsync | C14: Pubblico | D14: Annulla, se la fascia non è finita | E14: PrenotazioneController
A15: PrenotazioniService | B15: AutomaticCompletPrenotazioniAsync | C15: Pubblico | D15: Di notte chiude le in corso e segna le non presentate | E15: PrenotazioniJob
... A69: DbExceptionTranslator | B69: IsUniqueViolation | C69: Pubblico | D69: Riconosce un doppione rifiutato dal database | E69: Servizi

Sheet BE · Validators
A1: BE · VALIDATORI — I CONTROLLI SUI DATI IN ARRIVO
A2: FluentValidation: se un controllo fallisce l'API risponde 400 con il messaggio in italiano. Cartella GestoraWebApi/Validators. | C2: ← Torna alla Dashboard
A4: Validatore | B4: Controlla | C4: Regole principali
A5: ZonaDTOValidator | B5: ZonaDTO | C5: Nome obbligatorio, max 100 caratteri
A6: PostazioneDTOValidator | B6: PostazioneDTO | C6: Numero, capienza e zona maggiori di zero
A7: PostazioneUpdateDTOValidator | B7: PostazioneUpdateDTO | C7: Id, numero, capienza e zona maggiori di zero
A8: FasciaOrariaDTOValidator | B8: FasciaOrariaDTO | C8: Orari «HH:mm» validi, fine dopo l'inizio (max 23:59), tetto > 0, giorno 0-6
A9: PrenotazioneCreateDTOValidator | B9: PrenotazioneCreateDTO | C9: Coperti da 1 a 50, data fra oggi e un anno, fascia valida, note max 500
A10: CheckDisponibilitaDTOValidator | B10: CheckDisponibilitaDTO | C10: Coperti da 1 a 50, data fra oggi e un anno
A11: RegisterDTOValidator | B11: RegisterDTO | C11: Nome 3-50 caratteri, email valida, password min 8 con maiuscola, numero e simbolo
A12: UpdateUserDTOValidator | B12: UpdateUserDTO | C12: Se presenti: nome 3-50 caratteri, email valida
A13: AdminResetPasswordDTOValidator | B13: AdminResetPasswordDTO | C13: Password min 8 con maiuscola, numero e simbolo

Sheet BE · Infrastruttura
A1: BE · INFRASTRUTTURA — CONFIGURAZIONE, ERRORI, AVVIO
A2: Quello che non è logica di prenotazione ma fa funzionare l'API: Program.cs, Infrastructure, Extensions, Development. | C2: ← Torna alla Dashboard
A4: Componente | B4: Tipo | C4: Cosa fa
A5: ExceptionMiddleware | B5: Middleware | C5: Trasforma ogni errore in una risposta JSON chiara
A6: NotFoundException | B6: Eccezione | C6: → 404: elemento non trovato
A7: ValidationException / ArgumentException | B7: Eccezione | C7: → 400: dati non validi
A8: UnauthorizedAccessException | B8: Eccezione | C8: → 401: non autenticato
A9: ForbiddenException | B9: Eccezione | C9: → 403: operazione non permessa
A10: ConflictException | B10: Eccezione | C10: → 409: conflitto (es. doppione, tetto pieno)
A11: Qualsiasi altro errore | B11: Eccezione | C11: → 500: errore interno
A12: DbExceptionTranslator | B12: Eccezione | C12: Riconosce i doppioni rifiutati dal database
A13: IdentityErrorDescriberItaliano | B13: Eccezione | C13: Messaggi di Identity in italiano
A14: AuthenticationExtensions | B14: Estensione | C14: Configura Identity, JWT e il controllo del security stamp
A15: SwaggerSetup | B15: Estensione | C15: Pagina Swagger, solo in sviluppo
... A34: docker-publish.yml | B34: Deploy | C34: Test, poi immagine su Docker Hub → Azure

Sheet BE · Test
A1: BE · TEST — xUnit + Moq
A2: N. test conta anche i casi delle [Theory]. Si lanciano dalla radice con: dotnet test Gestora.sln. Cartella GestoraWebApi.Tests. | E2: ← Torna alla Dashboard
A3: Totale test: | B3: =SUM(D5:D1000) -> 292
A4: Classe di test | B4: Cosa prova | C4: Tecnica | D4: N. test | E4: Note
A5: PrenotazioniServiceTests | B5: PrenotazioniService | C5: Database finto + Moq | D5: 101 | E5: Il blocco più grande: tetto, stati, regole, job
A6: DashboardServiceTests | B6: DashboardService | C6: Database finto | D6: 25
A7: FasciaOrariaServiceTests | B7: FasciaOrariaService | C7: Moq | D7: 16 | E7: Accavallamenti e blocco degli orari
A8: AssegnazioneTavoliTests | B8: AssegnazioneTavoli | C8: Puro (senza dipendenze) | D8: 15 | E8: Scelta dei tavoli e bonus testate
A9: PostazioneAssignmentServiceTests | B9: PostazioneAssignmentService | C9: Moq | D9: 13
A10: IndirizzoClientTests | B10: IndirizzoClient | C10: Puro | D10: 13 | E10: Lettura dell'IP da X-Forwarded-For
A11: DisponibilitaServiceTests | B11: DisponibilitaService | C11: Moq | D11: 12
A12: PostazioneServiceTests | B12: PostazioneService | C12: Moq | D12: 12
A13: LogActivityServiceTests | B13: LogActivityService | C13: Database finto | D13: 10
A14: PrenotazioniQueryParamsTests | B14: PrenotazioniQueryParams | C14: Puro | D14: 9 | E14: Pagine e filtri
A15: CheckDisponibilitaDTOValidatorTests | B15: CheckDisponibilitaDTOValidator | C15: Validatore | D15: 11
A16: PrenotazioneCreateDTOValidatorTests | B16: PrenotazioneCreateDTOValidator | C16: Validatore | D16: 12
A17: RegisterDTOValidatorTests | B17: RegisterDTO e UpdateUserDTO | C17: Validatore | D17: 7 | E17: Nomi con spazi, apostrofi, accenti
A18: FasciaOrariaDTOValidatorTests | B18: FasciaOrariaDTOValidator | C18: Validatore | D18: 5 | E18: Fasce oltre la mezzanotte
A19: ZonaServiceTests | B19: ZonaService | C19: Moq | D19: 8
A20: DbExceptionTranslatorTests | B20: DbExceptionTranslator | C20: Puro | D20: 6
A21: JobsNotturniTests | B21: PrenotazioniJob, PrenotazioniCleanupJob | C21: Moq | D21: 4
A22: GestoraContextModelTests | B22: GestoraContext | C22: Database finto | D22: 3 | E22: Configurazione delle tabelle
A23: PrenotazioniRepositoryTests | B23: PrenotazioniRepository | C23: Database finto | D23: 3
A24: PrenotazioneMappingProfileTests | B24: PrenotazioneMappingProfile | C24: AutoMapper vero | D24: 3
A25: PostazioneMappingProfileTests | B25: PostazioneMappingProfile | C25: AutoMapper vero | D25: 2
A26: ErroriIdentityTests | B26: ErroriIdentity | C26: Puro | D26: 2

Sheet BE · Auth e Security
A1: BE · AUTENTICAZIONE E SICUREZZA
A2: Mai scrivere qui valori segreti: solo i nomi delle chiavi. Procedura User Secrets in RUNBOOK.md §7. | C2: ← Torna alla Dashboard
A4: Sezione | B4: Voce | C4: Come funziona
A5: JWT | B5: Chiavi di configurazione | C5: JwtSettings: Secret, Issuer, Audience, ExpiryMinutes
A6: JWT | B6: Dove sta il segreto | C6: Locale: User Secrets. Produzione: variabili d'ambiente di Azure. Mai nel codice
A7: JWT | B7: Lunghezza minima | C7: Almeno 32 byte, altrimenti l'app non parte
A8: JWT | B8: Durata | C8: 60 minuti, senza margine di tolleranza
A9: JWT | B9: Contenuto | C9: Id utente, email, ruoli, security stamp
A10: JWT | B10: Controlli | C10: Chi l'ha emesso, per chi, scadenza e firma
A11: Ruoli | B11: Admin | C11: Configura sala e fasce, gestisce utenti, forza i job
A12: Ruoli | B12: Staff | C12: Prenotazioni e dashboard
A13: Ruoli | B13: Cliente | C13: Solo le proprie prenotazioni
A14: Ruoli | B14: Più ruoli insieme | C14: Normale, non è un errore
A15: Ruoli | B15: Admin protetto | C15: Un Admin non può togliersi il ruolo Admin: ne resta sempre almeno uno
... A29: Protezioni | B29: Libreria con avviso | C29: AutoMapper 12.0.1: avviso accettato, non si aggiorna (SEC-001)

Sheet BE · Jobs
A1: BE · JOB NOTTURNI — QUARTZ.NET
A2: Ora di Roma, mai due esecuzioni insieme, stato salvato nelle tabelle QRTZ_. Su Azure F1 partono al primo accesso del giorno (serve «Always On»). | F2: ← Torna alla Dashboard
A4: Job | B4: Quando | C4: Cron | D4: Cosa fa | E4: Metodo chiamato | F4: Come forzarlo (Admin)
A5: PrenotazioniJob | B5: Ogni notte alle 02:00 | C5: 0 00 2 * * ? | D5: Chiude le prenotazioni in corso finite e segna «Non presentata» chi non è arrivato | E5: AutomaticCompletPrenotazioniAsync | F5: POST /api/Jobs/trigger/PrenotazioniJob
A6: PrenotazioniCleanupJob | B6: Ogni notte alle 02:30 | C6: 0 30 2 * * ? | D6: Elimina le prenotazioni chiuse più vecchie di 6 mesi | E6: AutomaticDeletePrenotazioniAsync | F6: POST /api/Jobs/trigger/PrenotazioniCleanupJob

Sheet BE · Migration
A1: BE · MIGRATION — MODIFICHE AL DATABASE
A2: Si applicano A MANO, dall'alto in basso (RUNBOOK.md). Le tabelle QRTZ_ di Quartz non sono in nessuna migration: dopo un reset va eseguito Scripts/quartz_postgres.sql. | G2: ← Torna alla Dashboard
A4: N. | B4: Nome migration | C4: Data | D4: Cosa cambia | E4: Locale | F4: Produzione | G4: Note
A5: 1 | B5: 20251120171458_Initial | C5: 45981 | D5: Crea tutte le tabelle e quelle di Identity (Utenti, Ruoli) | E5: Sì | F5: Sì
A6: 2 | B6: 20260311090312_StatoAsEnum | C6: 46092 | D6: Nessuna modifica: vuota di proposito | E6: Sì | F6: Sì | G6: Non è un errore
A7: 3 | B7: 20260825141722_FilterIndicePrenotazioneEscludeAnnullata | C7: 46259 | D7: Indice sulle prenotazioni che ignora le annullate | E7: Sì | F7: Sì
A8: 4 | B8: 20260826133929_RimuoviVincoloIndiceAggiungiNomeCliente | C8: 46260 | D8: Aggiunge NomeCliente, toglie il vincolo una-al-giorno dal database | E8: Sì | F8: Sì | G8: Il vincolo resta nell'applicazione (decisione 10)
A9: 5 | B9: 20260831094313_RinominaMaxPrenotazioniInMaxCoperti | C9: 46265 | D9: Rinomina MaxPrenotazioni in MaxCoperti | E9: Sì | F9: Sì | G9: Da qui: usare sempre lo script generato
A10: 6 | B10: 20260902081401_AggiungiSlotPrenotazionePostazione | C10: 46267 | D10: Data e fascia sul legame tavolo-prenotazione + indice unico | E10: Sì | F10: Sì | G10: Un tavolo non si prenota due volte
A11: 7 | B11: 20260904141854_AuditLogIndiciEStoricoUtenteProtetto | C11: 46269 | D11: Indici sul registro; utente con prenotazioni non eliminabile | E11: Sì | F11: Sì

Sheet FE · Pagine
A1: FE · PAGINE — LE SCHERMATE E CHI LE VEDE
A2: Rotte in gestora-frontend/src/router/index.tsx. Le pagine riservate stanno dentro AppLayout (barra superiore). | D2: ← Torna alla Dashboard
A4: Indirizzo | B4: Pagina | C4: Chi la vede | D4: Cosa fa
A5: / | B5: LandingPage | C5: Tutti (chi è collegato va alla sua pagina) | D5: Presenta il locale e controlla se c'è posto
A6: /setup | B6: SetupPage | C6: Tutti, solo finché non c'è un Admin | D6: Crea il primo Admin
A7: /login | B7: LoginPage | C7: Tutti | D7: Accesso
A8: /register | B8: RegisterPage | C8: Tutti | D8: Registrazione come Cliente
A9: /dashboard | B9: DashboardPage | C9: Admin, Staff | D9: Numeri del giorno e della settimana
A10: /zone | B10: ZonePage | C10: Admin, Staff | D10: Elenco e gestione delle zone
A11: /postazioni | B11: PostazionePage | C11: Admin, Staff | D11: Tavoli e riepilogo della sala
A12: /fasce-orarie | B12: FasciaOrariaPage | C12: Admin, Staff | D12: Fasce orarie e tetti dei coperti
A13: /prenotazioni | B13: PrenotazionePage | C13: Admin, Staff, Cliente | D13: Prenotazioni: elenco, filtri, azioni
A14: /admin-utenti | B14: AdminUtentiPage | C14: Admin | D14: Utenti, ruoli e password
A15: /unauthorized | B15: UnauthorizedPage | C15: Tutti | D15: Avviso: pagina non permessa
A16: * | B16: NotFoundPage | C16: Tutti | D16: Pagina non trovata

Sheet FE · Componenti
A1: FE · COMPONENTI — I PEZZI DELLE SCHERMATE
A2: Cartella gestora-frontend/src/components (struttura piatta, i componenti base in ui/). | D2: ← Torna alla Dashboard
A4: Componente | B4: Tipo | C4: Cosa fa | D4: Usato in
A5: ZonaModal | B5: Finestra | C5: Crea o modifica una zona | D5: ZonePage
A6: PostazioneModal | B6: Finestra | C6: Crea o modifica un tavolo | D6: PostazionePage
A7: FasciaOrariaModal | B7: Finestra | C7: Crea o modifica una fascia | D7: FasciaOrariaPage
A8: PrenotazioneModal | B8: Finestra | C8: Crea o modifica una prenotazione | D8: PrenotazionePage
A9: NotaPrenotazioneDialog | B9: Finestra | C9: Mostra la nota di una prenotazione | D9: PrenotazionePage
A10: CreateUserModal | B10: Finestra | C10: Crea un utente con ruolo | D10: AdminUtentiPage
A11: EditUserModal | B11: Finestra | C11: Modifica nome o email | D11: AdminUtentiPage
A12: GestisciRuoliModal | B12: Finestra | C12: Dà o toglie ruoli | D12: AdminUtentiPage
A13: ResetPasswordModal | B13: Finestra | C13: Imposta una nuova password | D13: AdminUtentiPage
A14: ConfirmDialog | B14: Finestra | C14: Chiede conferma prima di un'azione | D14: Più pagine
A15: AppLayout | B15: Struttura | C15: Barra superiore con menu per ruolo | D15: Pagine riservate
... A32: ui/ (shadcn) | B32: UI base | C32: Pulsanti, tabelle, finestre, campi, menu, etichette | D32: Tutti i componenti

Sheet FE · Hook e API
A1: FE · HOOK E CHIAMATE ALL'API
A2: Ogni hook usa TanStack Query e chiama l'API con apiClient (src/lib/axios.ts). Indirizzi in src/lib/endpoints.ts, base /api. | F2: ← Torna alla Dashboard
A4: Hook | B4: Area | C4: Verbo | D4: Endpoint | E4: Cosa fa | F4: File
A5: useZone | B5: Zone | C5: GET | D5: Zona/get-all-zone | E5: Tutte le zone | F5: useZone.ts
A6: useZoneAttive | B6: Zone | C6: GET | D6: Zona/get-zone-attive | E6: Zone attive | F6: useZone.ts
A7: useCreaZona | B7: Zone | C7: POST | D7: Zona/crea-zona | E7: Crea una zona | F7: useZone.ts
A8: useUpdateZona | B8: Zone | C8: PUT | D8: Zona/update-zona | E8: Modifica una zona | F8: useZone.ts
A9: useDeleteZona | B9: Zone | C9: DELETE | D9: Zona/delete-zona/{id} | E9: Elimina una zona | F9: useZone.ts
A10: usePostazioni | B10: Tavoli | C10: GET | D10: Postazione/get-postazioni-per-zona | E10: Tavoli di una zona | F10: usePostazioni.ts
A11: useRiepilogoSala | B11: Tavoli | C11: GET | D11: Postazione/riepilogo-sala | E11: Riepilogo della sala | F11: usePostazioni.ts
A12: useCreaPostazione | B12: Tavoli | C12: POST | D12: Postazione/crea-postazione | E12: Crea un tavolo | F12: usePostazioni.ts
A13: useUpdatePostazione | B13: Tavoli | C13: PUT | D13: Postazione/update-postazione | E13: Modifica un tavolo | F13: usePostazioni.ts
A14: useDeletePostazione | B14: Tavoli | C14: DELETE | D14: Postazione/delete-postazione | E14: Elimina un tavolo | F14: usePostazioni.ts
A15: useFasceOrarie | B15: Fasce orarie | C15: GET | D15: FasceOrarie/fasce-attive | E15: Fasce attive | F15: useFasceOrarie.ts
... A43: useTheme | B43: Altro | C43: — | D43: — | E43: Tema chiaro o scuro | F43: useAuth.ts / useTheme.ts

Sheet FE · Auth
A1: FE · ACCESSO E PERMESSI NEL FRONTEND
A2: Il frontend nasconde e reindirizza; il vero controllo dei permessi lo fa sempre il backend. | C2: ← Torna alla Dashboard
A4: Voce | B4: Dove | C4: Come funziona
A5: Token | B5: src/context/AuthContext.tsx | C5: Salvato in localStorage dopo il login, tolto al logout
A6: Lettura del token | B6: src/lib/jwt.ts | C6: Legge ruoli e scadenza dal token (senza verificarlo: lo fa il backend)
A7: Ruoli | B7: src/context/AuthContext.tsx | C7: Sempre trattati come elenco: un utente può averne più di uno
A8: Allegare il token | B8: src/lib/axios.ts | C8: Aggiunto a ogni chiamata, tranne login e registrazione
A9: Sessione scaduta | B9: src/lib/axios.ts + session.ts | C9: Su 401 toglie il token e mostra un solo avviso, poi porta al login
A10: Pagine riservate | B10: src/router/ProtectedRoute.tsx | C10: Non collegato → /login; ruolo sbagliato → /unauthorized
A11: Primo avvio | B11: src/router/SetupGuard.tsx | C11: Se non c'è un Admin manda a /setup
A12: Già collegato | B12: src/router/RedirectSeAutenticato.tsx | C12: Da / o /login manda alla pagina giusta per il ruolo
A13: Pagina di casa | B13: src/lib/navigazione.ts | C13: Sceglie la pagina iniziale in base al ruolo
A14: Menu | B14: src/layouts/AppLayout.tsx | C14: Mostra solo le voci permesse al ruolo
A15: Nuovi tentativi | B15: src/lib/queryClient.ts | C15: Nessun nuovo tentativo su errori 4xx e sulle modifiche
... A17: Indirizzo API | B17: VITE_API_URL | C17: Locale da .env.local, produzione dal pannello Vercel (tipo Config)

Sheet FE · Test
A1: FE · TEST — Vitest + Testing Library
A2: Si lanciano da gestora-frontend con: npm test. I file stanno nelle cartelle __tests__. | C2: ← Torna alla Dashboard
A3: Totale test: | B3: =SUM(C5:C1000) -> 64
A4: File di test | B4: Cosa prova | C4: N. test
A5: AzioniPrenotazione.test.tsx | B5: Pulsanti delle prenotazioni: compaiono solo quando permessi | C5: 16
A6: apiError.test.ts | B6: Messaggi di errore leggibili dalle risposte dell'API | C6: 11
A7: jwt.test.ts | B7: Lettura del token e scadenza | C7: 10
A8: validazioni.test.ts | B8: Regole di password, nome utente, email, numeri | C8: 8
A9: ProtectedRoute.test.tsx | B9: Pagine riservate: login e ruoli | C9: 6
A10: PrenotazioneModal.fasce.test.tsx | B10: Fasce proposte nella finestra prenotazione | C10: 5
A11: navigazione.test.ts | B11: Pagina iniziale giusta per ogni ruolo | C11: 5
A12: PrenotazionePage.urlParams.test.tsx | B12: Filtri letti dall'indirizzo della pagina | C12: 2
A13: DashboardPage.dateNav.test.tsx | B13: Cambio di giorno nella dashboard | C13: 1

Sheet Appunti e Step
A1: APPUNTI E STEP
A2: Da compilare a mano: una riga per sessione o per passo. Area e Stato hanno il menu a tendina. | F2: ← Torna alla Dashboard
A4: Data | B4: Area | C4: Cosa si è fatto | D4: Prossimo passo | E4: Stato | F4: Note
A5: 46297 | B5: Deploy | C5: Controllo regressioni sui 4 commit del 02/10: codice dell'app invariato, 292 test BE e 64 FE verdi, build come nel Dockerfile riuscita | D5: Al prossimo merge dev → main aprire Actions: job «test» verde con 292 test, poi «build-and-push» verde, poi /health su Azure | E5: Fatto | F5: Il workflow docker-publish è cambiato (test dalla radice) ma non è mai girato: parte solo su main
A6: 46297 | B6: Repository | C6: .gitignore in radice sporco: blocco ripetuto due volte e una riga di testo finita per errore («- toglie il doppione di .vs/ e la riga di GestoraDocs.») | D6: Togliere il blocco doppio e la riga sbagliata, poi commit «chore: .gitignore senza righe doppie» | E6: Fatto | F6: Non rompe niente. File delicato (regola 3): lo modifica Fabio o autorizza Claude
A7: 46297 | B7: BE | C7: Test spostati in GestoraWebApi.Tests/ e soluzione Gestora.sln in radice | D7: Aprire Gestora.sln in Visual Studio, Esplora test: devono risultare 292 test verdi | E7: Fatto
A8: 46297 | B8: Deploy | C8: Stato della CI non controllabile da Claude (gh non installato) | D8: Controllare su GitHub che CI Backend e CI Frontend siano verdi sull'ultimo commit di dev | E8: Fatto | F8: Dopo il push del riordino Fabio ha visto la CI verde

Sheet Fix e Bug
A1: FIX E BUG
A2: Da compilare a mano: un difetto per riga. Area, Gravità e Stato hanno il menu a tendina. | I2: ← Torna alla Dashboard
A4: ID | B4: Data | C4: Area | D4: Dove | E4: Problema | F4: Gravità | G4: Soluzione | H4: Stato | I4: Chiuso il
A5: CAP-002 | B5: 46297 | C5: BE | D5: PrenotazioneCreateDTOValidator, CheckDisponibilitaDTOValidator; FE: VerificaDisponibilita.tsx | E5: Il tetto di 50 coperti per prenotazione è fisso nel codice | F5: Bassa | G5: Renderlo configurabile: A) valore in appsettings (consigliata) o B) impostazione dell'Admin nel database | H5: Aperto
